Workbook

Sheet Graphs
Q1: Count | R1: Company Name | S1: Request Log | T1: Request Date | U1: Request Link | V1: Referral Received | W1: Comment | X1: Message Ready | Y1: Resume Ready
M19: Important Links for Applications
M20: 1. Networking Message | N20: Link
M21: 2. Resume | N21: Link
M22: 3. Cover Letter | N22: Link
M23: 4. Extra Documents | N23: Link
M24: 5. Screenshots | N24: Link
M25: 6. Cover Letter Template | N25: Link
M62: I hope you're doing well! I previously worked as an SDE2 at Bounteous and am pursuing my Master’s in Data Science from Stony Brook University. I came across the Software Developer 2026 ELH position with Job ID: 91689, and wanted to check if you’d be open to reviewing my resume or referring me. Thank you!
S87: #REF!

Sheet Saved Jobs
A1: Date Saved | B1: Role | C1: Company | D1: Location | E1: Job Link
A2: 45961.71 | B2: Computational Imaging Research Scientist Manage My Job Request a Coach | C2: GLASS Imaging | D2: San Francisco Bay Area · 10 minutes ago · 0 applicants Promoted by hirer · No response insights available yet | E2: https://www.linkedin.com/jobs/view/4320212741/
A3: 45961.724 | B3: Embedded Software Engineer Manage My Job Request a Coach | C3: Vastika Inc | D3: Carrollton, TX · 15 minutes ago · 5 applicants Promoted by hirer · No response insights available yet | E3: https://www.linkedin.com/jobs/view/4320312705/
A4: 45961.734 | B4: AI Engineer | C4: New Resources Consulting | D4: Milwaukee, WI · Reposted 51 minutes ago · Over 100 applicants Promoted by hirer · Actively reviewing applicants | E4: https://www.linkedin.com/jobs/view/4314022965/
A5: 45961.76 | B5: Quantitative Strategy Developer - New Grad Manage My Job Request a Coach | C5: Susquehanna International Group | D5: Greater Philadelphia · 38 minutes ago · 17 people clicked apply Promoted by hirer · Responses managed off LinkedIn | E5: https://www.linkedin.com/jobs/view/4320152787/
A6: 45961.831 | B6: Devops Engineer | C6: Wipro | D6: Minneapolis, NC · 3 hours ago · 25 people clicked apply Promoted by hirer · Responses managed off LinkedIn | E6: https://www.linkedin.com/jobs/view/4320212736/
A7: 45961.837 | B7: Software Engineer – Microsoft AI Manage My Job Request a Coach | C7: Microsoft | D7: Redmond, WA · 3 hours ago · 48 people clicked apply Promoted by hirer · Responses managed off LinkedIn | E7: https://www.linkedin.com/jobs/view/4333328595/
A8: 45961.87 | B8: Real-Time /Embedded Firmware Engineer | C8: Nuvoton Technology Corporation America | D8: Austin, TX · 49 minutes ago · 6 applicants Promoted by hirer · Company review time is typically 1 week | E8: https://www.linkedin.com/jobs/view/4333369385/
A9: 45961.872 | B9: Front End Engineer- React & Map API Manage My Job Request a Coach | C9: Ascendion | D9: Seattle, WA · Reposted 54 minutes ago · Over 100 applicants Promoted by hirer · Actively reviewing applicants | E9: https://www.linkedin.com/jobs/view/4315044235/
A10: 45962.411 | B10: Applications Analyst Manage My Job Request a Coach | C10: Zekelman Industries | D10: Wheatland, PA · Reposted 42 minutes ago · 27 people clicked apply Promoted by hirer · Responses managed off LinkedIn | E10: https://www.linkedin.com/jobs/view/4313443958/
A11: 45963.12 | B11: AI Engineer Manage My Job Request a Coach | C11: Avesta Computer Services | D11: Fremont, CA · 42 minutes ago · 3 applicants Promoted by hirer · No response insights available yet | E11: https://www.linkedin.com/jobs/view/4332188017/
A12: 45963.13 | B12: Senior Web Developer Manage My Job Request a Coach | C12: SCIENTIFIC GAMES | D12: Alpharetta, GA · Reposted 10 minutes ago · 99 people clicked apply Promoted by hirer · Responses managed off LinkedIn | E12: https://www.linkedin.com/jobs/view/4309207109/
A13: 45963.198 | B13: Software Development Engineer III | C13: Optimum | D13: Bethpage, NY · Reposted 1 hour ago · Over 100 people clicked apply Responses managed off LinkedIn | E13: https://www.linkedin.com/jobs/view/4177889291/
... A67: 45969.997 | B67: Software Engineer Manage My Job Request a Coach | C67: Benchmark | D67: New York, NY · 1 month ago · Over 100 applicants Promoted by hirer · Actively reviewing applicants | E67: https://www.linkedin.com/jobs/view/4310415694/
A68: 11/13/2025, 12:00:00 AM | B68: Software Engineer | C68: Miller Cooper | D68: Remote | E68: https://millercooper.atsondemand.com/#/jobDescription/904556
A69: =IFERROR(__xludf.DUMMYFUNCTION("IFERROR( FILTER( { ARRAYFORMULA(TEXT(TO_DATE(Jobright!B2:B975), ""MM/dd/yyyy, h:mm:ss AM/PM"")), Jobright!A2:A975, Jobright!F2:F975, Jobright!E2:E975, Jobright!C2:C975, Jobright!M2:M975 }, LOWER(TRIM(Jobri"&"ght!M2:M975))=""Done"" ), ""No rows marked done"" ) "),"No rows marked done") -> No rows marked done
A70: 45975.53 | B70: Data Scientist - New Grad (2026 Start) Manage My Job Request a Coach | C70: Databricks | D70: Mountain View, CA · Reposted 7 hours ago · Over 100 people clicked apply Promoted by hirer · Responses managed off LinkedIn | E70: https://www.linkedin.com/jobs/view/4297746037/
A71: 45975.537 | B71: Quality Engineer Manage My Job Request a Coach | C71: Oerlikon | D71: Westbury, NY · Reposted 7 hours ago · 46 people clicked apply Promoted by hirer · Responses managed off LinkedIn | E71: https://www.linkedin.com/jobs/view/4306806143/
A72: 45975.537 | B72: Software Engineer Manage My Job Request a Coach | C72: Akamai Technologies | D72: United States · 1 minute ago · 0 people clicked apply Promoted by hirer · Responses managed off LinkedIn | E72: https://www.linkedin.com/jobs/view/4336231580/
A73: 45975.884 | B73: Software Engineer Backend/Platform Systems I (Full Time) – United States Manage My Job Request a Coach | C73: Cisco | D73: Fulton, MD · 19 minutes ago · 6 people clicked apply Promoted by hirer · Responses managed off LinkedIn | E73: https://www.linkedin.com/jobs/view/4336294749/
A74: 45975.886 | B74: Machine Learning Engineer, Strategy & Supply Optimization | C74: DoorDash | D74: San Francisco, CA · 46 minutes ago · 0 people clicked apply Promoted by hirer · Responses managed off LinkedIn | E74: https://www.linkedin.com/jobs/view/4340833443/
A75: 45975.887 | B75: Software Engineer Manage My Job Request a Coach | C75: Lowe's Companies, Inc. | D75: Charlotte, NC · 47 minutes ago · 5 people clicked apply Responses managed off LinkedIn | E75: https://www.linkedin.com/jobs/view/4322675546/
A76: 45975.892 | B76: (USA) Senior, Data Engineer Manage My Job Request a Coach | C76: Walmart | D76: Sunnyvale, CA · 20 minutes ago · 4 people clicked apply Promoted by hirer · Responses managed off LinkedIn | E76: https://www.linkedin.com/jobs/view/4340554040/
A77: 45975.898 | B77: Data Engineer Manage My Job Request a Coach | C77: Aquent | D77: Austin, TX · Reposted 1 hour ago · 3 people clicked apply Promoted by hirer · Responses managed off LinkedIn | E77: https://www.linkedin.com/jobs/view/4336284362/
A78: 45976.979 | B78: Data Engineer Manage My Job Request a Coach | C78: Tupl Inc. | D78: Dallas, TX · 1 day ago · Over 100 people clicked apply Promoted by hirer · Responses managed off LinkedIn | E78: https://www.linkedin.com/jobs/view/4335949863/
A79: 45976.996 | B79: Backend Engineer Manage My Job Request a Coach | C79: Bevel | D79: New York, NY · 1 week ago · Over 100 people clicked apply Responses managed off LinkedIn | E79: https://www.linkedin.com/jobs/view/4334860779/
A80: 45977.86 | B80: Software Engineer (Networking) Manage My Job Request a Coach | C80: ORDR | D80: Santa Clara, CA · 9 hours ago · 86 applicants Promoted by hirer · No response insights available yet | E80: https://www.linkedin.com/jobs/view/4322941297/
A81: 45977.86 | B81: New Grad | C81: Optiver | D81: Chicago | E81: https://optiver.com/working-at-optiver/career-opportunities/7986419002/?gh_jid=7986419002&gh_src=hk2so9u22us
... A175: 46000.022 | B175: Structural Designer Quick Apply | C175: Kiewit | D175: Omaha, NE · 1 week ago · 42 applicants Promoted by hirer · No response insights available yet | E175: https://www.linkedin.com/jobs/view/4324872849/
A176: 46000 | E176: https://nvidia.wd5.myworkdayjobs.com/en-US/NVIDIAExternalCareerSite/userHome
A177: 46000 | E177: https://www.linkedin.com/in/shaun-blair-25621812/
A178: 46000.035 | B178: Software Developer (GPS/GNSS):: 25-07166 Quick Apply | C178: Akraya, Inc. | D178: Mountain View, CA · Reposted 32 minutes ago · 9 applicants Promoted by hirer · No response insights available yet | E178: https://www.linkedin.com/jobs/view/4348389382/
A179: 46000.035 | B179: Epic Cadence/Referrals Analyst Quick Apply | C179: TEKsystems | D179: Virginia Beach, VA · Reposted 7 minutes ago · 0 people clicked apply Promoted by hirer · Responses managed off LinkedIn | E179: https://www.linkedin.com/jobs/view/4342588218/
A180: 46000.036 | B180: *Technical Specialist (Healthcare) Quick Apply | C180: Cotiviti | D180: United States · Reposted 17 minutes ago · Over 100 people clicked apply Promoted by hirer · Responses managed off LinkedIn | E180: https://www.linkedin.com/jobs/view/4325308202/
A181: 46000.038 | B181: Senior Software Engineer I, New Product Development Quick Apply | C181: Axon | D181: Seattle, WA · 11 minutes ago · 1 person clicked apply Responses managed off LinkedIn | E181: https://www.linkedin.com/jobs/view/4342667947/
A182: 46000.039 | B182: Software Engineer – PEGA (Full-Stack Growth Path) Quick Apply | C182: Intuit | D182: Mountain View, CA · 1 hour ago · 20 people clicked apply Promoted by hirer · Responses managed off LinkedIn | E182: https://www.linkedin.com/jobs/view/4342697468/
A183: 46000.045 | B183: Software Engineer Quick Apply | C183: ServiceNow | D183: Santa Clara, CA · 1 hour ago · Over 100 people clicked apply Promoted by hirer · Responses managed off LinkedIn | E183: https://www.linkedin.com/jobs/view/4342707707/
A184: 46000.048 | B184: Software Engineer – PEGA (Full-Stack Growth Path) Quick Apply | C184: Intuit | D184: New York, NY · 2 hours ago · 15 people clicked apply Promoted by hirer · Responses managed off LinkedIn | E184: https://www.linkedin.com/jobs/view/4342786882/
A185: 46000.051 | B185: Test Engineer Quick Apply | C185: swipejobs | D185: Brea, CA · 2 hours ago · 11 people clicked apply Promoted by hirer · Responses managed off LinkedIn | E185: https://www.linkedin.com/jobs/view/4342697461/
A186: 46000.052 | B186: Software Engineer Quick Apply | C186: Lowe's Companies, Inc. | D186: Charlotte, NC · 2 hours ago · Over 100 people clicked apply Promoted by hirer · Responses managed off LinkedIn | E186: https://www.linkedin.com/jobs/view/4342777380/
...

Sheet Pending Work 23th Feb
A1: Count | B1: Company Name | C1: Position Name | D1: Current Date | E1: Updated Date | F1: Comment | G1: Link
A2: 1 | B2: Nvidia | C2: Solution Architect | D2: 46075 | G2: https://nvidia.wd5.myworkdayjobs.com/NVIDIAExternalCareerSite/job/US-CA-Santa-Clara/Solutions-Architect--Worldwide-Field-Operations---New-College-Graduate-2026_JR2004686?source=Eightfold
A3: 2 | B3: Zip | C3: Software Engineer, New Grad (2026 Start) | D3: 46075 | F3: I need to reach out to the recuiter regarding the message suggested by gpt | G3: https://www.linkedin.com/in/bhavani-nkrishna/ | H3: Hi Bhavani, I just applied for the Software Engineer role at Zip via Ashby and wanted to introduce myself. I came across your profile through mutual connections and thought I’d reach out in case you’re the right person to speak with or can point me to the appropriate recruiter. Thanks for your time.

Sheet YCDI
A15: 46068 | B15: Android Engineer (Growth & Ecosystem) | C15: https://jobright.ai/jobs/info/68e7d8a9c4895107182bec62?utm_source=1100&utm_campaign=Software Engineering | D15: On Site | E15: Boston, MA | F15: WHOOP | G15: $105K-$145K /yr | H15: 501-1000 | I15: Consumer Electronics, Fitness | J15: 1. 0–2 years of professional experience in Android development (internship or academic experience acceptable) 2. Proficiency with Kotlin and familiarity with Android Studio and Jetpack libraries 3. Understanding of Android fundamentals including lifecycle, UI components, and REST API integration 4. Enthusiasm for writing clean code and collaborating in a team environment 5. Willingness to learn architecture patterns like MVVM and modular design ... | K15: not sure | L15: yes
A16: 46068 | B16: Software Engineer - Core Product | C16: https://jobright.ai/jobs/info/6991b50c6ea51a7610f40e53?utm_source=1100&utm_campaign=Software Engineering | D16: Remote | E16: New York, NY | F16: Baseten | G16: $150K-$230K /yr | H16: 101-250 | I16: AI Infrastructure, Artificial Intelligence (AI) | J16: 1. Bachelor's degree or higher in Computer Science or related field 2. 1-3 years experience in software engineering or infrastructure 3. Proficient coding abilities in one or more popular programming or scripting languages; Python, Go, or Javascript proficiency is a plus 4. Familiarity with web applications & databases 5. Good taste in product, particularly developer-oriented tools ... | K16: not sure
A17: 46068 | B17: Software Engineer - C++ Core Middleware | C17: https://jobright.ai/jobs/info/68cee4ad846f0b04af67d99a?utm_source=1100&utm_campaign=Software Engineering | D17: Hybrid | E17: Foster City, CA | F17: Zoox | G17: $175K-$212K /yr | H17: 1001-5000 | I17: Artificial Intelligence (AI), Autonomous Vehicles | J17: 1. 1+ years of professional software development experience 2. Strong proficiency in modern C++ (C++14/17) 3. Strong background in developing scalable, distributed applications in Linux and the Nvidia Drive platform 4. Experience with GPU/CUDA programming 5. Experience with robotics frameworks/middleware (e.g., ROS/ROS2) | K17: not sure
A18: 46068 | B18: Associate R & D Data Scientist | C18: https://jobright.ai/jobs/info/69580d75f1f8465b79eeaf5b?utm_source=1100&utm_campaign=Software Engineering | D18: Remote | E18: Princeton, NJ | F18: ETS | G18: N/A | H18: 5001-10000 | I18: Association, EdTech | J18: 1. Demonstrable proficiency and experience in Python and/or R for data analysis and modeling. 2. Hands-on experience with PyTorch/TensorFlow, Scikit-learn, and other machine learning frameworks. 3. Familiarity with generative AI methods and their practical applications. 4. Strong understanding of statistical methods, experimental design, and data visualization. 5. Ability to work in cloud computing environments (e.g., AWS) for model deployment and data processing. ... | K18: not sure
A19: 46068 | B19: Embedded NPU Software Engineer | C19: https://jobright.ai/jobs/info/69840c1f01214b4cdacc6e42?utm_source=1100&utm_campaign=Software Engineering | D19: On Site | E19: San Diego, CA | F19: Qualcomm | G19: $94200-$141200 /yr | H19: 10000+ | I19: Artificial Intelligence (AI), Generative AI | J19: 1. Bachelor's degree in Engineering, Information Systems, Computer Science, or related field. 2. Develop and validate embedded NPU software features in C/C++ for real-time systems. 3. Participate in the design and implementation of inter-processor communication and memory management mechanisms. 4. Assist in debugging, profiling, and optimizing software for performance and power efficiency. 5. Collaborate with cross-functional teams to integrate NPU software into broader system frameworks. ... | K19: not sure
A20: 46068 | B20: Deep Learning Kernel Software Performance Architect - New College Grad 2026, Deep Learning Kernel Software Performance Architect - New College Grad 2026 | C20: https://jobright.ai/jobs/info/69743bf0206da320f49e61ae?utm_source=1100&utm_campaign=Software Engineering | D20: On Site | E20: Santa Clara, CA | F20: NVIDIA | G20: $124K-$242K /yr | H20: 10000+ | I20: AI Infrastructure, Artificial Intelligence (AI) | J20: 1. Master's or PhD in Computer Science, Electrical Engineering or Computer Engineering, or equivalent experience. 2. Proven expertise in software design, including debugging, performance analysis, and test development 3. Hands-on experience with practical parallel programming, even if it’s not on GPUs. 4. Strong understanding of computer architecture, with practical experience on performance debugging. 5. Ability to identify bottlenecks, optimize resource utilization, and enhance system throughput ... | K20: not sure
A21: 46069 | B21: Systems Programmer I | C21: https://jobright.ai/jobs/info/6994d97fe0bddb6acac35703?utm_source=1100&utm_campaign=Software Engineering | D21: Hybrid | E21: St Charles, IL | F21: OSG USA, INC. | G21: $56K-$73K /yr | H21: 101-250 | I21: Industrial, Manufacturing | J21: 1. HS Diploma/GED or equivalent 2. Experience computer programming in X++, C#, and/or SQL 3. Experience with Microsoft Office Products 4. Excellent problem-solving and analytical skills 5. Basic knowledge of database management, SQL, and data modeling | K21: not sure
A22: 46069 | B22: El Mirage, Arizona- Network Infrastructure Engineer – Data Center | C22: https://jobright.ai/jobs/info/6993e38e81476f6176ab8092?utm_source=1100&utm_campaign=Software Engineering | D22: On Site | E22: El Mirage, AZ | F22: Catapult Federal Services | G22: $75K-$85K /yr | H22: 11-50 | J22: 1. 1–3 years of hands-on experience in a network support or systems administration role. 2. Comfortable working in active construction and commissioning environments and wearing required personal protective equipment (PPE) such as steel-toe boots, hard hats, and safety vests. 3. Ability to perform physical tasks including standing for extended periods, working in equipment racks, and lifting or moving network hardware as required. 4. Strong understanding of LAN/WAN fundamentals, including IP addressing, subnetting, VLANs, and routing. 5. Hands-on experience with Cisco networking equipment (switching and routing). ... | K22: not sure
A23: 46069 | B23: Zoho Developer | C23: https://jobright.ai/jobs/info/69955c76ce78e77b4fd97ff7?utm_source=1100&utm_campaign=Software Engineering | D23: Remote | E23: Remote job | F23: KDG | G23: $65000-$75000 /yr | H23: 11-50 | I23: Cyber Security, Digital Marketing | J23: 1. Demonstrated professional integrity, accountability, and ethical judgment, with a consistent commitment to doing what is right for the client, the team, and the business. 2. Strong business-first mindset, viewing technology as a tool to support operational efficiency, scalability, and long-term success—not as an end in itself. 3. Proven ability to communicate clearly and respectfully with Project Managers, Business Analysts, and customers, translating complex ideas into practical, shared understanding. 4. High sense of ownership and responsibility, following through on commitments, proactively addressing challenges, and taking pride in delivering meaningful outcomes. 5. Thoughtful and disciplined approach to listening, clarifying, and validating requirements before designing or building solutions. ... | K23: not sure
A24: 46069 | B24: System Administrator 1 | C24: https://jobright.ai/jobs/info/6993cedb81476f6176ab6a58?utm_source=1100&utm_campaign=Software Engineering | D24: Hybrid | E24: La Crosse, WI | F24: Kwik Trip, Inc. | G24: $27-$40 /hr | H24: 10000+ | I24: Consumer Goods, Food and Beverage | J24: 1. Associate degree in Information Systems/Network Systems Administration or equivalent combination of education and experience is required. 2. Experience related to server and infrastructure management, with specific focus on the setup and maintenance of servers and applications within a virtual environment. 3. Knowledge of Microsoft Windows client and server operating systems 4. Experience with Office 365 administration (including Exchange Online, SharePoint Online, etc.) 5. Experience with Microsoft Active Directory, and Microsoft Group Policy management. ... | K24: not sure
A25: 46069 | B25: Flight Software Engineer | C25: https://jobright.ai/jobs/info/6993f025e0bddb6acac23b53?utm_source=1100&utm_campaign=Software Engineering | D25: On Site | E25: San Francisco, CA | F25: Astro Mechanica | G25: $90K-$160K /yr | H25: 46032 | I25: Aerospace, Manufacturing | J25: 1. Bachelor’s degree in Computer Science, Engineering, Math, or a Science discipline 2. 0-3 years of professional software development experience, including internships and research experience 3. Experience in C++, Rust, or other systems programming language 4. Proven skills in debugging, performance optimization, and unit testing 5. Ambition to work in a fast-paced environment | K25: not sure | L25: yes
A26: 46069 | B26: INFORMATION TECHNOLOGY SPECIALIST I | C26: https://jobright.ai/jobs/info/6994d12081476f6176aca282?utm_source=1100&utm_campaign=Software Engineering | D26: Hybrid | E26: Sacramento, CA | F26: California State Treasurer's Office | G26: $6513-$10852 /mon | H26: 101-250 | I26: Banking, Education | J26: 1. The position(s) require(s) a Background Investigation be cleared prior to being hired. 2. Current version of the State Examination/Employment Application STD Form 678 (when not applying electronically), or the Electronic State Employment Application through your Applicant Account at www.CalCareers.ca.gov. All Experience and Education relating to the Minimum Qualifications listed on the Classification Specification should be included to demonstrate how you meet the Minimum Qualifications for the position. 3. Resume is required and must be included. 4. School Transcripts | K26: not sure
A27: 46069 | B27: Computer Science and Engineering Department: CROSS Practitioner in Residence Pool | C27: https://jobright.ai/jobs/info/6995703f81476f6176ad606f?utm_source=1100&utm_campaign=Software Engineering | D27: On Site | E27: Santa Cruz County, CA | F27: Waco Tribune-Herald | G27: $55000-$194800 /yr | H27: 101-250 | I27: Fitness, News | J27: 1. Bachelor’s degree or higher (or equivalent foreign degree). 2. Experience in open source software development. | K27: yes
A28: 46069 | B28: Software Engineer - Simulators | C28: https://jobright.ai/jobs/info/6997ded6e0bddb6acac6b3d6?utm_source=1100&utm_campaign=Software Engineering | D28: Hybrid | E28: Mountain View, CA | F28: MatX | G28: $120000-$200000 /yr | H28: 11-50 | I28: AI Infrastructure, Artificial Intelligence (AI) | J28: 1. Bachelor of Computer Science or equivalent degree 2. Excellent software engineering skills, with a focus on maintainable performant 3. Strong foundation in computer architecture fundamentals 4. Excellent cross-functional communication skills 5. Rust experience AND/OR experience writing cycle-accurate simulators ... | K28: not sure | L28: yes
A29: 46069 | B29: System Development Engineer I, REALM | C29: https://jobright.ai/jobs/info/6993d865ce78e77b4fd7abc3?utm_source=1100&utm_campaign=Software Engineering | D29: On Site | E29: Bellevue, Washington, USA | F29: Amazon | G29: $99,100-$160,000 /yr | H29: 10000+ | I29: Artificial Intelligence (AI), Delivery | J29: 1. Experience in automating, deploying, and supporting infrastructure 2. Experience programming with at least one modern language such as Python, Ruby, Golang, Java, C++, C#, Rust 3. Experience with Linux/Unix 4. 1+ years of DevOps or SysOps in a large-scale software development environment experience 5. Bachelor's degree in computer science, computer engineering, or related field | K29: not sure
A30: 46069 | B30: Data Engineer | C30: https://jobright.ai/jobs/info/69939ba3ce78e77b4fd76e5c?utm_source=1100&utm_campaign=Software Engineering | D30: Hybrid | E30: Multi Location Utah, United States Washington, United States Colorado, United States Oregon, United States | F30: Slalom | G30: $91000-$122000 /yr | H30: 10000+ | I30: Collaboration, Consulting | J30: 1. Experience with Big Data Platforms (Apache Spark, Presto, Amazon EMR) 2. Experience with Cloud Data Warehouses (Amazon Redshift, Snowflake, Google BigQuery) 3. Proficiency in Object Oriented Coding (Java, Python) 4. Experience with NoSQL Databases (DynamoDB, Cosmos DB, MongoDB) 5. Familiarity with Container Management Systems (Kubernetes, Amazon ECS) ... | K30: not sure
A31: 46069 | B31: Software Engineer, Autonomy-New Grad | C31: https://jobright.ai/jobs/info/693e643baa598a08c3eeb026?utm_source=1100&utm_campaign=Software Engineering | D31: On Site | E31: Mountain View, CA | F31: Nuro | G31: $145K-$219K /yr | H31: 501-1000 | I31: Artificial Intelligence (AI), Autonomous Vehicles | J31: 1. You are a recent graduate or graduating soon (BS, MS or PhD) with focus on one or more of the areas listed above 2. You are a skilled algorithm designer with strong problem solving 3. You are a talented software developer ideally with experience in C++/Python 4. You have experience working with machine learning or autonomous systems 5. You have a knack and real passion for searching and solving hard problems ... | K31: not sure | L31: yes
A32: 46069 | B32: Data Engineer | C32: https://jobright.ai/jobs/info/6993adeb81476f6176ab485f?utm_source=1100&utm_campaign=Software Engineering | D32: Remote | E32: 400 NW Plz Dr, St Ann, MO 63074, USA | F32: Save A Lot | G32: $85300-$107000 /yr | H32: 1001-5000 | I32: Food Processing | J32: 1. 1-3 years of IT experience 2. 1-3 years of experience with Python 3. 1-3 years of experience with SQL 4. 1-3 years of experience delivering projects in a complex enterprise environment 5. 1-3 years developing and delivering data engineering solutions in data warehousing ... | K32: not sure
A33: 46069 | B33: AI Prompt Engineer Associate (DMV) | C33: https://jobright.ai/jobs/info/6993f5c9ce78e77b4fd7d33f?utm_source=1100&utm_campaign=Software Engineering | D33: Remote | E33: Any Location / Remote | F33: General Dynamics Information Technology | G33: $80750-$109250 /yr | H33: 10000+ | I33: Artificial Intelligence (AI), Cloud Computing | J33: 1. Education: Bachelor of Arts/Bachelor of Science or High School Degree 2. Experience: 0+ years of related experience with BA/BS or 4 years of relevant experience with High School Degree 3. Excellent problem-solving skills with creative mindset 4. Strong communication skills to collaborate with other program members and stakeholders 5. Curiosity about AI systems, how they work, and how to optimize generative AI responses ... | K33: not sure | L33: yes
A34: 46069 | B34: App Review Specialist | C34: https://jobright.ai/jobs/info/699365a581476f6176ab059c?utm_source=1100&utm_campaign=Software Engineering | D34: On Site | E34: Sunnyvale, California, United States | F34: Apple | G34: $27.75-$47.02 /hr | H34: 10000+ | I34: Apps, Artificial Intelligence (AI) | J34: 1. Fluency in English and Spanish as this role will frequently be supporting language-specific apps. 2. Available to work a Tuesday–Saturday schedule. | K34: not sure
A35: 46069 | B35: Software Engineer | C35: https://jobright.ai/jobs/info/68afbe89b47fb001d688cc34?utm_source=1100&utm_campaign=Software Engineering | D35: Hybrid | E35: Seattle, WA | F35: Aircall | G35: $140K-$190K /yr | H35: 501-1000 | I35: Analytics, Call Center | J35: 1. At least 1 year of professional experience in back-end or full-stack development 2. Expert level programming ability with Typescript (+React), Python, or Ruby 3. Deep understanding of software development practices, scalable system architecture, security best practices and cloud-based platforms 4. Proven understanding of distributed computing principles and experience with cloud-based platforms 5. Exceptional analytical and problem-solving skills, with the ability to effectively troubleshoot complex data issues ... | K35: not sure
A36: 46069 | B36: Machine Learning Engineer l | C36: https://jobright.ai/jobs/info/68cddf34e23def7af55bfd8a?utm_source=1100&utm_campaign=Software Engineering | D36: Remote | E36: United States | F36: Cohere Health | G36: $95K-$115K /yr | H36: 501-1000 | I36: Consumer Software, Health Care | J36: 1. 1-3 years full time professional experience in ML 2. MS in computer science, machine learning, computational linguistics, statistics, mathematics or similar field 3. Hands on experience building with modern language models, including context-engineering LLMs or fine-tuning SLMs 4. Understanding of scientific best practice in experimental design and can independently perform data collection, measurement, and interpretation of results 5. Experience configuring, training, evaluating, deploying, and maintaining models in a production setting ... | K36: not sure
A37: 46069 | B37: AI Automation & Growth Analyst | C37: https://jobright.ai/jobs/info/6993231081476f6176aacbce?utm_source=1100&utm_campaign=Software Engineering | D37: On Site | E37: Los Angeles, CA | F37: Warner Music Group | G37: $70K-$80K /yr | H37: 1001-5000 | I37: Digital Entertainment, Media and Entertainment | J37: 1. Strong Scripting Skills (Python or JavaScript): You have strong hands-on experience using Python or JavaScript/TypeScript for data manipulation, API interaction, and process automation. You prefer writing a script to doing a task manually twice. 2. Data & SQL Fluency: You are comfortable writing SQL queries to pull, clean, and structure data from relational databases. You understand how to prepare data for AI context windows. 3. Version Control (Git): You understand the importance of source control. You are familiar with branching, merging, and pull requests to maintain a clean codebase in a team environment. 4. LLM & API Experience: You have built applications or scripts that utilize LLM APIs (OpenAI, Anthropic, Gemini). You understand concepts like context limits, temperature, and prompt engineering within code. 5. Grounded in Engineering Principles: You build for the long term. You strive to write clean, scalable, and reliable code that can be maintained and built upon by the team. ... | K37: not sure
A38: 46069 | B38: Software Engineer II, Backend (Credit Decisioning) | C38: https://jobright.ai/jobs/info/69766b97bc8e722e7b1b01c5?utm_source=1100&utm_campaign=Software Engineering | D38: Remote | E38: Multi Location Las Vegas, NV Denver, CO Atlanta, GA Houston, TX New York, NY San Diego, CA Portland, OR Pittsburgh, PA Salt Lake City, UT Detroit, MI Richmond, VA Boulder, CO Washington, DC Cleveland, OH Sioux Falls, SD Palo Alto, CA San Francisco, CA Minneapolis, MN Raleigh, NC Dallas, TX Nashville, TN Phoenix, AZ Boston, MA Chicago, IL Austin, TX Los Angeles, CA Philadelphia, PA San Jose, CA Madison, WI St Louis, MO Charlotte, NC Seattle, WA Miami, FL Baltimore, MD Boise, ID | F38: Affirm | G38: $160,000-$210,000 /yr | H38: 1001-5000 | I38: Financial Services, FinTech | J38: 1. You have a total of 1.5+ years of experience as a software engineer. 2. You have experience designing, developing and launching backend systems and are proficient in one of Python or Kotlin. 3. You are familiar with the building blocks of distributed systems, and the technologies like AWS, MySQL and Kubernetes. 4. You have mastered taking a simple problem or business scenario into a solution that interacts with multiple software components, and executing on it by writing clear, easily understood, well tested and extensible code. 5. You are comfortable navigating a large code base, debugging others' code, and providing feedback to other engineers through code reviews. ... | K38: not sure
A39: 46069 | B39: Game Test Analyst | C39: https://jobright.ai/jobs/info/690b95204a1b456627b10975?utm_source=1100&utm_campaign=Software Engineering | D39: On Site | E39: San Diego, CA | F39: Sony Interactive Entertainment | G39: $17-$18 /hr | H39: 10000+ | I39: Consumer Goods, Music | J39: 1. Must be at least 18 years of age 2. Strong analytical and problem solving skills 3. Excellent written and verbal communication (needs to be able to communicate bugs how did you find them? What exact steps are needed to make it happen again?) 4. Basic to intermediate understanding of networking setup and hardware, as well as how its principles and components apply to modern console, PC, and mobile gaming / functionality 5. Ability to work in both an individual and team environment ... | K39: not sure
A40: 46069 | B40: Junior Full Stack Engineer ($250k - $300k salary) | C40: https://jobright.ai/jobs/info/69933bb7e0bddb6acac18538?utm_source=1100&utm_campaign=Software Engineering | D40: On Site | E40: New York, NY | F40: Baton Corporation | G40: $250K-$300K /yr | H40: 11-50 | J40: 1. An exceptional early-career engineer with a strong foundation in computer science and the ability to ramp quickly on new systems and codebases 2. Studied at a top university or demonstrated equivalent ability through competitive programming, Olympiads, open-source contributions, or substantial personal projects 3. Comfortable working across the stack, with hands-on experience in technologies like TypeScript, React, Next.js, and Node.js (or adjacent modern frameworks) 4. Curious and intellectually rigorous - you enjoy understanding why systems work, not just how to use them 5. A strong problem solver who can break down ambiguous problems, reason from first principles, and iterate toward solid solutions ... | K40: not sure
A41: 46069 | B41: QA Analyst (Temp) | C41: https://jobright.ai/jobs/info/69485501d1953b5d11c1610e?utm_source=1100&utm_campaign=Software Engineering | D41: On Site | E41: Austin, TX | F41: Daybreak Game Company LLC | G41: $14-$17 /hr | H41: 501-1000 | I41: Gamification, Gaming | J41: 1. Proficient in QA Methodologies and best practices 2. Excellent written and verbal communication 3. 1 year of quality assurance experience 4. Create and execute test plans 5. Collaborate with other analysts and developers to ensure thorough testing of content ... | K41: not sure
A42: 46069 | B42: Engineer II - Software Defined Storage | C42: https://jobright.ai/jobs/info/6976c169206da320f4a077ca?utm_source=1100&utm_campaign=Software Engineering | D42: Hybrid | E42: Multi Location Palo Alto, CA Chevy Chase, MD Seattle, WA Dallas, TX | F42: GEICO | G42: $75K-$160K /yr | H42: 10000+ | I42: Auto Insurance, Financial Services | J42: 1. Understanding of various storage architectures and solutions, including object storage (with technologies like Amazon S3, OpenStack Swift), block storage (using software like iSCSI, Fibre Channel), and file storage (solutions such as NFS, SMB/CIFS) 2. Proficiency with data management and storage protocols/services (e.g., Fibre Channel, iSCSI, NFS, SMB/CIFS) 3. Familiarity with virtualization technologies (e.g., VMware, Hyper-V) and their interaction with underlying storage infrastructures 4. Understanding of and experience with software-defined storage services such as Ceph, MinIO, Swift, OpenStack, and GlusterFS 5. Proficiency with cloud services and infrastructure, including public and private cloud environments ... | K42: yes
A43: 46069 | B43: Trade Systems Engineer | C43: https://jobright.ai/jobs/info/6806869622b8e29f156721fb?utm_source=1100&utm_campaign=Software Engineering | D43: On Site | E43: Chicago, IL | F43: DRW | G43: $85K-$125K /yr | H43: 1001-5000 | I43: Consulting, Finance | J43: 1. 1–3 years of experience in trade support, systems administration, site reliability engineering, or a related technical role (internships or projects count!) 2. Bachelor’s degree in Computer Science, Engineering, or related STEM field 3. Basic understanding of networking concepts (TCP/IP, DNS, DHCP) and ability to use common troubleshooting tools 4. Ability to think through and troubleshoot technical problems under time pressure 5. Clear communication skills, written and verbal ... | K43: not sure
A44: 46070 | B44: Production Engineer, Global Banking & Markets, FICC Systematic Market Making (SMM) | C44: https://jobright.ai/jobs/info/69957643e0bddb6acac40d5e?utm_source=1100&utm_campaign=Software Engineering | D44: On Site | E44: Multi Location New York, NY New York, New York, United States | F44: Goldman Sachs | G44: $115000-$180000 /yr | H44: 10000+ | I44: Banking, Finance | J44: 1. 1 year or more of relevant work experience 2. Proficiency in one of the following: Python, C, C++, Java, or shell scripting 3. Aptitude for algorithms, data structures, and software design 4. Experience with Linux operating system internals and/or networking concepts 5. Strong analytical skills, with an ability to quickly identify scope and impact of issues during high-pressure situations ... | K44: not sure
A45: 46070 | B45: Software Engineer | C45: https://jobright.ai/jobs/info/6997e315e0bddb6acac6bdac?utm_source=1100&utm_campaign=Software Engineering | D45: On Site | E45: Sioux Falls, SD | F45: Sanford Health | G45: $32-$52 /hr | H45: 10000+ | I45: Children, Education | J45: 1. Bachelor's Degree in a computer-related field required. 2. Basic knowledge of computer principles and techniques necessary to develop and document software applications systems. 3. Basic knowledge of relational databases. 4. Basic knowledge of Object Oriented programming. 5. Basic knowledge of ASP.NET. ... | K45: not sure
A46: 46070 | B46: Firmware Validation Engineer & Flashing Engineer | C46: https://jobright.ai/jobs/info/6995608fce78e77b4fd98621?utm_source=1100&utm_campaign=Software Engineering | D46: On Site | E46: Palo Alto, CA | F46: Tesla | G46: $140000-$210000 /yr | H46: 10000+ | I46: Automotive, Electric Vehicle | J46: 1. Minimum of 1 to 3 years prior experience in embedded systems, software engineering (or similar role) 2. Bachelor’s Degree in Computer Science, Electrical Engineering, Computer Engineering, or related field, or equivalent experience 3. Solid Python experience 4. Understanding of branching, configuration management, testing, build and release processes for complex software 5. Must have fundamentals in electrical engineering ... | K46: not sure
A47: 46070 | B47: Firmware Validation Engineer & Flashing Engineer | C47: https://jobright.ai/jobs/info/69955f92ce78e77b4fd98538?utm_source=1100&utm_campaign=Software Engineering | D47: On Site | E47: Palo Alto, CA | F47: Tesla | G47: $140K-$210K /yr | H47: 10000+ | I47: Automotive, Electric Vehicle | J47: 1. Minimum of 1 to 3 years prior experience in embedded systems, software engineering (or similar role) 2. Bachelor’s Degree in Computer Science, Electrical Engineering, Computer Engineering, or related field, or equivalent experience 3. Solid Python experience 4. Understanding of branching, configuration management, testing, build and release processes for complex software 5. Must have fundamentals in electrical engineering ... | K47: not sure
A48: 46070 | B48: IT Systems Engineer | C48: https://jobright.ai/jobs/info/69955b49e0bddb6acac3eb98?utm_source=1100&utm_campaign=Software Engineering | D48: Hybrid | E48: San Francisco, CA | F48: You.com | G48: $90K-$120K /yr | H48: 51-100 | I48: Artificial Intelligence (AI), Chatbot | J48: 1. Bachelor's degree in Information Technology, Computer Science, or a related field (or equivalent practical experience). 2. 0–2 years of professional IT support experience. 3. Demonstrable Python and Bash scripting ability (personal projects, coursework, or professional experience). 4. Familiarity with Git/GitHub workflows. 5. Understand how to use command line on Linux and MacOS. | K48: not sure | L48: yes
A49: 46070 | B49: Software Engineer I / II - San Francisco | C49: https://jobright.ai/jobs/info/68f95f5acadb2e5a06a64637?utm_source=1100&utm_campaign=Software Engineering | D49: On Site | E49: Multi Location San Francisco, CA San Francisco Bay Area | F49: Giga | G49: $160K-$250K /yr | H49: 11-50 | I49: Artificial Intelligence (AI), B2C | J49: 1. 1-3 years of professional software engineering experience 2. Curious and ask good questions—you want to understand why things work, not just how 3. Can take feedback well and iterate quickly 4. Prefer shipping over perfection but still care about quality 5. Want to grow at a startup where you'll have real responsibility early | K49: not sure
A50: 46070 | B50: Junior Systems Administrator | C50: https://jobright.ai/jobs/info/6995b059ce78e77b4fd9c70f?utm_source=1100&utm_campaign=Software Engineering | D50: Hybrid | E50: Washington, DC | F50: Urban Land Institute | G50: $56K-$67K /yr | H50: 51-100 | I50: Association, Real Estate | J50: 1. Working knowledge of Windows 10/11 2. Working knowledge of macOS and iOS 3. Working knowledge of Microsoft 365 applications 4. Working knowledge of Active Directory and Azure Active Directory 5. Exposure to cloud platforms (Azure, AWS, or Google Workspace) preferred but not required ... | K50: not sure
A51: 46070 | B51: Associate Machine Learning Engineer | C51: https://jobright.ai/jobs/info/69955e8b81476f6176ad4958?utm_source=1100&utm_campaign=Software Engineering | D51: On Site | E51: SD Metro Area | F51: XiFin, Inc. | G51: $70K-$100K /yr | H51: 501-1000 | I51: Enterprise Software, Health Care | J51: 1. Bachelor’s or Master’s degree in Computer Science, Engineering, Data Science, or a related technical field 2. 0–3 years of programming experience in Python (including academic projects, internships, research, or personal projects) 3. Foundational understanding of data structures, algorithms, and software development principles 4. Demonstrated interest in artificial intelligence, automation, and applied machine learning 5. Demonstrate a strong growth mindset and eagerness to learn emerging AI technologies ... | K51: not sure | L51: yes
A52: 46070 | B52: Entry-Level Embedded Systems Engineer | C52: https://jobright.ai/jobs/info/69957131ce78e77b4fd99c9e?utm_source=1100&utm_campaign=Software Engineering | D52: On Site | E52: Allentown, PA | F52: Broadcom | G52: $73K-$117K /yr | H52: 10000+ | I52: Mobile, Semiconductor | J52: 1. Master’s Degree in Electrical Engineering or Computer Engineering 2. Proficient in C and Python 3. Self-directed and motivated | K52: not sure
A53: 46070 | B53: Security Engineer, New Grad | C53: https://jobright.ai/jobs/info/699949e6e0bddb6acac868fe?utm_source=1100&utm_campaign=Software Engineering | D53: Hybrid | E53: Multi Location San Francisco, CA Seattle, WA | F53: Stripe | G53: $129K-$193K /yr | H53: 5001-10000 | I53: Finance, FinTech | J53: 1. Currently enrolled in a Bachelor’s or Master’s program in Computer Science or related field (graduating by Summer 2026) 2. Some experience and familiarity with programming, either through side projects or classwork. We work mostly in Java, Ruby, Python, JavaScript, Scala, and Go. We believe new programming languages can be learned if the fundamentals and general knowledge are present 3. Experience from either previous internships or working collaboratively on multi-person coding projects (in a university or professional setting) 4. Ability to learn unfamiliar systems and form an understanding of those systems, through independent research and working with a mentor and subject matter experts 5. Aptitude to think like an attacker and reason through different approaches to reducing security risk. | K53: not sure | L53: yes
A54: 46070 | B54: R&D Engineer, Embedded Systems (Onsite) | C54: https://jobright.ai/jobs/info/6995dbe7e0bddb6acac44bfd?utm_source=1100&utm_campaign=Software Engineering | D54: On Site | E54: Sunnyvale,CA,US | F54: EBR Systems, Inc. | G54: $87500-$112500 /yr | H54: 51-100 | I54: Biotechnology, Health Care | J54: 1. Bachelor’s degree in Electrical Engineering, Computer Engineering, Embedded Systems, or related field. 2. Entry-level role with up to 2 years of experience (industry or strong academic projects). 3. Exposure to embedded C/C++, microcontrollers, and basic electronics concepts. 4. Curiosity, persistence, and comfort working through ambiguity. 5. Willingness to ask questions and learn from failures. ... | K54: not sure | L54: yes
...

Sheet Archive Referral List
A1: Count | B1: Company Name | C1: Request Log | D1: Request Date | E1: Updated Date | F1: Request Link | G1: Referral Received | H1: Comment | I1: Message Ready | J1: Resume Ready
A2: 1 | B2: Snapchat | C2: Snapchat - Software Engineer Machine Learning - H126SWEMLI2 | D2: 46071 | F2: https://wd1.myworkdaysite.com/en-US/recruiting/snapchat/snap/job/Software-Engineer--ML-Infrastructure--Level-4_H126SWEMLI2-1 | G2: Reject | H2: Ananya: Mostly i was 2 weeks late for the position
A3: 2 | B3: Snapchat | C3: Snapchat - Software Engineer Backend - Q126SWEB2 | D3: 46071 | G3: Applied | H3: sai
A4: 3 | B4: Snowflake | C4: Snoflake - Software Engineer - ASHREQ-5421 | D4: 46071 | F4: https://careers.snowflake.com/us/en/job/SNCOUS7791AB6A66D34A20BCE877FFC470EA41EXTERNALENUS5F4AE8D3BF84430D8F9F325F14DDF947/Software-Engineer-APG?utm_source=Q2P9NP2NNP&utm_medium=phenom-feeds&gh_src=ed5543a62 | G4: Requested
A5: 4 | B5: Stripe | C5: Stripe - Software Engineering - New Grad | D5: 46071 | F5: https://stripe.com/jobs/listing/software-engineer-new-grad/7210112?gh_src=73vnei | G5: Requested
A6: 5 | B6: Google | C6: Google - Software Engineering II | D6: 46069 | G6: Applied
A7: 6 | B7: Amazon | C7: Amazon SDE | D7: 46069 | G7: Applied | H7: Meet*2
A8: 7 | B8: Amazon | C8: Amazon Software Engineering | D8: 46069 | G8: Applied | H8: Sradha
A9: 8 | B9: Cisco | C9: Cisco - 2007003 Software Engineer 1 | D9: 46068 | G9: Applied | H9: Aman Jain
A10: 9 | B10: Bounteous | C10: Software Engineering | D10: 46068 | G10: Applied | H10: Ankit Jain
A11: 10 | B11: Microsoft | C11: Software Engineering | D11: 46073 | G11: Requested | H11: Desi Runner Community he said he will reply today a k a 21st of feb
A12: 11 | B12: Gold Man Sach | C12: Software Engineering | D12: 46073 | G12: Applied | H12: Sai
A13: 12 | B13: Amazon | C13: Software Development Engineer | D13: 46073 | F13: https://www.amazon.jobs/en/jobs/3185058/software-development-engineer?cmpid=SPLICX0248M&utm_source=jobright&utm_campaign=cxro&utm_medium=social_media&utm_content=job_posting&ss=paid | G13: Requested | H13: Meet
A14: 13 | B14: Stackline | C14: Full Stack Engineer | D14: 46073 | F14: https://boards.greenhouse.io/embed/job_app?token=4613319005&utm_source=jobright | G14: Requested
A15: 14 | B15: Cisco | C15: Software Engineering 2 ID2007168 | F15: https://careers.cisco.com/global/en/job/2007168/Software-Engineer-II-Full-Time-United-States | G15: Pending | H15: Yash | I15: ID2007168
A17: 16 | B17: Rivian | C17: Software Engineer II, Full-Stack (QMS) | D17: 46075 | E17: 46075 | F17: https://internal-careers-rivian.icims.com/jobs/26472/software-engineer-ii%2c-full-stack-%28qms%29/job | G17: Message Ready | I17: I hope you're doing well! I previously worked as an SDE2 at Bounteous and am pursuing my Master’s in Data Science from Stony Brook University. I came across the Software Engineer II position with Job ID: 26472 at Rivian, and wanted to check if you’d be open to reviewing my resume or referring me. Thank you! | J17: Project Multi Purpose Resume
A18: 17 | B18: Paypal | C18: Software Engineer , Java | D18: 46074 | E18: 46075 | F18: http://paypal.eightfold.ai/careers/job/274917022927?source=JobBoardIndeed-Organic | G18: Requested | I18: I hope you're doing well! I previously worked as an SDE2 at Bounteous and am pursuing my Master’s in Data Science from Stony Brook University. I came across the Software Engineer, Java position with Job ID: R0133240 at Paypal, and wanted to check if you’d be open to reviewing my resume or referring me. Thank you!

Sheet Daily Rating
B1: DEC | C1: JAN | D1: FEB | E1: MAR | F1: APR | G1: MAY | H1: JUN | I1: JUL | J1: AUG | K1: SEP | L1: OCT | M1: NOV | N1: DEC
A2: 1
A3: 2
A4: 3
A5: 4
A6: 5
A7: 6
A8: 7
A9: 8
A10: 9
A11: 10
A12: 11
A13: 12
... A27: 26
A28: 27 | B28: P
A29: 28 | B29: P
A30: 29 | B30: P
A31: 30 | B31: P
A32: 31 | B32: P
P36: Amazing | S36: AP | T36: Academic Productive
P37: Good | S37: P | T37: Productive
P38: Mediocre | S38: NP | T38: Not at all Productive
P39: Poor | S39: ILL | T39: Literally ILL
P40: Nightmare | S40: D | T40: Demotivated
S41: ST | T41: Stressed

Sheet Daily Notes
A1: Date | B1: Comments
A2: 45992
A3: 29th December | B3: Mailroom Total time spent 11AM - 4PM not alot of work got some time to spend on resume but need to come up with a plan by EOY. Good: Recieved Deskmate (Manifestation works feels like) Bad: Alot of mails, told angelique about the missing timesheet Costco: Sirji got the membership spend around 2 hours store was mid but enjoyed Good: Bought Rice for 20.48$ cheaper then what i was placing order on Amazon same for 15LB Bad: Was not able to complete task in hand 1 Harriet St: Need to spend task being more productive, Fees paid by BOB finaily - Indian banking system need better people in this era tbh. Good: Starting of recording days sounds fun, got puma socks for 10 for 10 very good deal. Tried Spotify's feature to add 8 second of buffer mix between songs curently nuteral feeling to be honest Bad: Second time failed to make paneer, beacuse of the onions, need to keep it in mind that i have grid and cook at the same time. Droped my phone i guess i got a scratch but i still feel like without cover is my style Getting the feeling like i am becoming more like nanu where he used to record his feeling or daily activty in a dairy and i am using google sheets lol This feeling is not that i am getting old but more like i am getting more educated about life maybe but definatelty not because i am getting old for sure Miss you nanu
A4: 30th December | B4: Mailroom: Total Time spent 11AM - 4PM was tired because i didnt got a good amount of sleep yesterday mike point out 2 mistake, one in mail hunt and second one was non TBA scan then when i was talking to heather on phone i flaged one locker too, not my day at mailroom for sure. 1 Harriet St: Good: Fees think for Fall 2025 got resolved, got to eat watermaleon after years for sure, filled petrol for car 48$ Bad: Slept at 4 AM, Reached home at 5:30PM and slept till 8:30PM watched Demons Slayer and didnt have mood to do anything
A5: 31st December | B5: Mailroom: Reached exact 9AM today total time spent was 9:00AM - 1:00PM, did literally nothing till the time i am filling this daily notes. Hopefully i will be able to compelte the new sheet by eod today, need to think about the reusme format, need to apply for the RA posistion as well damn. 1 Harriet St: Good: It snowed for a while, mooraish flight got cancel sad, need to complete the sheet. Bad: Need to be more productive
A7: 46023 | B7: Expectation for the Month of January 2026: 1. Need to be more productive when it comes to job applications 2. You are gonna be turning 27 this year act like one take responsibilites make better decissions 3. Control your diet 4. 5.

Sheet Enhanced Jobs Data
A1: {='Saved Jobs'!A1:E995} -> Date Saved | B1: Role | C1: Company | D1: Location | E1: Job Link | F1: Date | G1: Month | H1: Week | I1: Day | J1: OA | K1: Referral | L1: Location | M1: Application Applied Time | N1: Number of Applicant | O1: OA Deadline | P1: Referral Count | Q1: Requested Referral Person Name | R1: Response | S1: Comment | Z1: Date | AA1: Week Number | AB1: Month | AC1: Week Start Date | AD1: Day Number
A2: 45961.71 | B2: Computational Imaging Research Scientist Manage My Job Request a Coach | C2: GLASS Imaging | D2: San Francisco Bay Area · 10 minutes ago · 0 applicants Promoted by hirer · No response insights available yet | E2: https://www.linkedin.com/jobs/view/4320212741/ | F2: =IFERROR(__xludf.DUMMYFUNCTION("ARRAYFORMULA( IF( A2:A995="""", , IFERROR( IF( ISNUMBER(A2:A995), TO_DATE(A2:A995), IFERROR( DATEVALUE(REGEXEXTRACT(A2:A995,""(\d{1,2}/\d{1,2}/\d{4})"")) + TIMEVALUE(REGEXEXTRACT(A2:A995,""(\"&"d{1,2}:\d{2}:\d{2}\s*[APMapm]{2})"")), IFERROR( DATEVALUE(REGEXEXTRACT(A2:A995,""(\d{4}-\d{2}-\d{2})"")) + TIMEVALUE(REGEXEXTRACT(A2:A995,""(\d{2}:\d{2}:\d{2})"")), DATEVALUE(A2:A995) ) ) "&" ), """" ) ) ) "),45961.70983796296) -> 45961.71 | G2: {=IF(F2:F995="",,TEXT(F2:F995,"mmm yyyy"))} -> Oct 2025 | H2: {=IF(F2:F995="",,WEEKNUM(F2:F995))} -> 44 | I2: {=IF(F2:F995="",,TEXT(F2:F995,"ddd"))} -> Fri | J2: =IF(A1<>"","No","") -> No | K2: =IF(A1<>"","No","") -> No | L2: =IFERROR(__xludf.DUMMYFUNCTION("ARRAYFORMULA( IF(D2:D995="""","""", { TRIM(IFERROR(REGEXEXTRACT(D2:D995,""^(.*?)·""),REGEXEXTRACT(D2:D995,""^(.*)$""))), TRIM(IFERROR(REGEXEXTRACT(D2:D995,""·\s*(.*?)\s*·""),"""")), IFERROR(VALUE(REGEXEXTRACT(D2:D995,""(\d+)"")),"""&""") } ) ) "),"San Francisco Bay Area") -> San Francisco Bay Area | M2: =IFERROR(__xludf.DUMMYFUNCTION("""COMPUTED_VALUE"""),"10 minutes ago") -> 10 minutes ago | N2: =IFERROR(__xludf.DUMMYFUNCTION("""COMPUTED_VALUE"""),10.0) -> 10 | P2: =IF(A1<>"","0","") -> 0 | R2: =IF(A1<>"","Review","") -> Review | Z2: {=IF(F2:F995="",,INT(F2:F995))} -> 45961 | AA2: {=IF(F2:F995="",,YEAR(F2:F995)&"-W"&TEXT(ISOWEEKNUM(F2:F995),"00"))} -> 2025-W44 | AB2: {=IF(F2:F995="",,TEXT(F2:F995,"yyyy-mm"))} -> 2025-10 | AC2: =IF(Z2="","", Z2 - WEEKDAY(Z2, 2) + 1) -> 45957 | AD2: =IF(Z2="","", WEEKDAY(Z2, 2)) -> 5
A3: 45961.724 | B3: Embedded Software Engineer Manage My Job Request a Coach | C3: Vastika Inc | D3: Carrollton, TX · 15 minutes ago · 5 applicants Promoted by hirer · No response insights available yet | E3: https://www.linkedin.com/jobs/view/4320312705/ | F3: =IFERROR(__xludf.DUMMYFUNCTION("""COMPUTED_VALUE"""),45961.72439814815) -> 45961.724 | G3: Oct 2025 | H3: 44 | I3: Fri | J3: =IF(A2<>"","No","") -> No | K3: =IF(A2<>"","No","") -> No | L3: =IFERROR(__xludf.DUMMYFUNCTION("""COMPUTED_VALUE"""),"Carrollton, TX") -> Carrollton, TX | M3: =IFERROR(__xludf.DUMMYFUNCTION("""COMPUTED_VALUE"""),"15 minutes ago") -> 15 minutes ago | N3: =IFERROR(__xludf.DUMMYFUNCTION("""COMPUTED_VALUE"""),15.0) -> 15 | P3: =IF(A2<>"","0","") -> 0 | R3: =IF(A2<>"","Review","") -> Review | Z3: 45961 | AA3: 2025-W44 | AB3: 2025-10 | AC3: =IF(Z3="","", Z3 - WEEKDAY(Z3, 2) + 1) -> 45957 | AD3: =IF(Z3="","", WEEKDAY(Z3, 2)) -> 5
A4: 45961.734 | B4: AI Engineer | C4: New Resources Consulting | D4: Milwaukee, WI · Reposted 51 minutes ago · Over 100 applicants Promoted by hirer · Actively reviewing applicants | E4: https://www.linkedin.com/jobs/view/4314022965/ | F4: =IFERROR(__xludf.DUMMYFUNCTION("""COMPUTED_VALUE"""),45961.73446759259) -> 45961.734 | G4: Oct 2025 | H4: 44 | I4: Fri | J4: =IF(A3<>"","No","") -> No | K4: =IF(A3<>"","No","") -> No | L4: =IFERROR(__xludf.DUMMYFUNCTION("""COMPUTED_VALUE"""),"Milwaukee, WI") -> Milwaukee, WI | M4: =IFERROR(__xludf.DUMMYFUNCTION("""COMPUTED_VALUE"""),"Reposted 51 minutes ago") -> Reposted 51 minutes ago | N4: =IFERROR(__xludf.DUMMYFUNCTION("""COMPUTED_VALUE"""),51.0) -> 51 | P4: =IF(A3<>"","0","") -> 0 | R4: =IF(A3<>"","Review","") -> Review | Z4: 45961 | AA4: 2025-W44 | AB4: 2025-10 | AC4: =IF(Z4="","", Z4 - WEEKDAY(Z4, 2) + 1) -> 45957 | AD4: =IF(Z4="","", WEEKDAY(Z4, 2)) -> 5
A5: 45961.76 | B5: Quantitative Strategy Developer - New Grad Manage My Job Request a Coach | C5: Susquehanna International Group | D5: Greater Philadelphia · 38 minutes ago · 17 people clicked apply Promoted by hirer · Responses managed off LinkedIn | E5: https://www.linkedin.com/jobs/view/4320152787/ | F5: =IFERROR(__xludf.DUMMYFUNCTION("""COMPUTED_VALUE"""),45961.76006944444) -> 45961.76 | G5: Oct 2025 | H5: 44 | I5: Fri | J5: Yes | K5: =IF(A4<>"","No","") -> No | L5: =IFERROR(__xludf.DUMMYFUNCTION("""COMPUTED_VALUE"""),"Greater Philadelphia") -> Greater Philadelphia | M5: =IFERROR(__xludf.DUMMYFUNCTION("""COMPUTED_VALUE"""),"38 minutes ago") -> 38 minutes ago | N5: =IFERROR(__xludf.DUMMYFUNCTION("""COMPUTED_VALUE"""),38.0) -> 38 | O5: 2nd Jan 3:18PM | P5: =IF(A4<>"","0","") -> 0 | R5: OA | Z5: 45961 | AA5: 2025-W44 | AB5: 2025-10 | AC5: =IF(Z5="","", Z5 - WEEKDAY(Z5, 2) + 1) -> 45957 | AD5: =IF(Z5="","", WEEKDAY(Z5, 2)) -> 5
A6: 45961.831 | B6: Devops Engineer | C6: Wipro | D6: Minneapolis, NC · 3 hours ago · 25 people clicked apply Promoted by hirer · Responses managed off LinkedIn | E6: https://www.linkedin.com/jobs/view/4320212736/ | F6: =IFERROR(__xludf.DUMMYFUNCTION("""COMPUTED_VALUE"""),45961.831041666665) -> 45961.831 | G6: Oct 2025 | H6: 44 | I6: Fri | J6: =IF(A5<>"","No","") -> No | K6: =IF(A5<>"","No","") -> No | L6: =IFERROR(__xludf.DUMMYFUNCTION("""COMPUTED_VALUE"""),"Minneapolis, NC") -> Minneapolis, NC | M6: =IFERROR(__xludf.DUMMYFUNCTION("""COMPUTED_VALUE"""),"3 hours ago") -> 3 hours ago | N6: =IFERROR(__xludf.DUMMYFUNCTION("""COMPUTED_VALUE"""),3.0) -> 3 | P6: =IF(A5<>"","0","") -> 0 | R6: =IF(A5<>"","Review","") -> Review | Z6: 45961 | AA6: 2025-W44 | AB6: 2025-10 | AC6: =IF(Z6="","", Z6 - WEEKDAY(Z6, 2) + 1) -> 45957 | AD6: =IF(Z6="","", WEEKDAY(Z6, 2)) -> 5
A7: 45961.837 | B7: Software Engineer – Microsoft AI Manage My Job Request a Coach | C7: Microsoft | D7: Redmond, WA · 3 hours ago · 48 people clicked apply Promoted by hirer · Responses managed off LinkedIn | E7: https://www.linkedin.com/jobs/view/4333328595/ | F7: =IFERROR(__xludf.DUMMYFUNCTION("""COMPUTED_VALUE"""),45961.83665509259) -> 45961.837 | G7: Oct 2025 | H7: 44 | I7: Fri | J7: =IF(A6<>"","No","") -> No | K7: =IF(A6<>"","No","") -> No | L7: =IFERROR(__xludf.DUMMYFUNCTION("""COMPUTED_VALUE"""),"Redmond, WA") -> Redmond, WA | M7: =IFERROR(__xludf.DUMMYFUNCTION("""COMPUTED_VALUE"""),"3 hours ago") -> 3 hours ago | N7: =IFERROR(__xludf.DUMMYFUNCTION("""COMPUTED_VALUE"""),3.0) -> 3 | P7: =IF(A6<>"","0","") -> 0 | R7: =IF(A6<>"","Review","") -> Review | Z7: 45961 | AA7: 2025-W44 | AB7: 2025-10 | AC7: =IF(Z7="","", Z7 - WEEKDAY(Z7, 2) + 1) -> 45957 | AD7: =IF(Z7="","", WEEKDAY(Z7, 2)) -> 5
A8: 45961.87 | B8: Real-Time /Embedded Firmware Engineer | C8: Nuvoton Technology Corporation America | D8: Austin, TX · 49 minutes ago · 6 applicants Promoted by hirer · Company review time is typically 1 week | E8: https://www.linkedin.com/jobs/view/4333369385/ | F8: =IFERROR(__xludf.DUMMYFUNCTION("""COMPUTED_VALUE"""),45961.86969907407) -> 45961.87 | G8: Oct 2025 | H8: 44 | I8: Fri | J8: =IF(A7<>"","No","") -> No | K8: =IF(A7<>"","No","") -> No | L8: =IFERROR(__xludf.DUMMYFUNCTION("""COMPUTED_VALUE"""),"Austin, TX") -> Austin, TX | M8: =IFERROR(__xludf.DUMMYFUNCTION("""COMPUTED_VALUE"""),"49 minutes ago") -> 49 minutes ago | N8: =IFERROR(__xludf.DUMMYFUNCTION("""COMPUTED_VALUE"""),49.0) -> 49 | P8: =IF(A7<>"","0","") -> 0 | R8: =IF(A7<>"","Review","") -> Review | Z8: 45961 | AA8: 2025-W44 | AB8: 2025-10 | AC8: =IF(Z8="","", Z8 - WEEKDAY(Z8, 2) + 1) -> 45957 | AD8: =IF(Z8="","", WEEKDAY(Z8, 2)) -> 5
A9: 45961.872 | B9: Front End Engineer- React & Map API Manage My Job Request a Coach | C9: Ascendion | D9: Seattle, WA · Reposted 54 minutes ago · Over 100 applicants Promoted by hirer · Actively reviewing applicants | E9: https://www.linkedin.com/jobs/view/4315044235/ | F9: =IFERROR(__xludf.DUMMYFUNCTION("""COMPUTED_VALUE"""),45961.87230324074) -> 45961.872 | G9: Oct 2025 | H9: 44 | I9: Fri | J9: =IF(A8<>"","No","") -> No | K9: =IF(A8<>"","No","") -> No | L9: =IFERROR(__xludf.DUMMYFUNCTION("""COMPUTED_VALUE"""),"Seattle, WA") -> Seattle, WA | M9: =IFERROR(__xludf.DUMMYFUNCTION("""COMPUTED_VALUE"""),"Reposted 54 minutes ago") -> Reposted 54 minutes ago | N9: =IFERROR(__xludf.DUMMYFUNCTION("""COMPUTED_VALUE"""),54.0) -> 54 | P9: =IF(A8<>"","0","") -> 0 | R9: =IF(A8<>"","Review","") -> Review | Z9: 45961 | AA9: 2025-W44 | AB9: 2025-10 | AC9: =IF(Z9="","", Z9 - WEEKDAY(Z9, 2) + 1) -> 45957 | AD9: =IF(Z9="","", WEEKDAY(Z9, 2)) -> 5
A10: 45962.411 | B10: Applications Analyst Manage My Job Request a Coach | C10: Zekelman Industries | D10: Wheatland, PA · Reposted 42 minutes ago · 27 people clicked apply Promoted by hirer · Responses managed off LinkedIn | E10: https://www.linkedin.com/jobs/view/4313443958/ | F10: =IFERROR(__xludf.DUMMYFUNCTION("""COMPUTED_VALUE"""),45962.41068287037) -> 45962.411 | G10: Nov 2025 | H10: 44 | I10: Sat | J10: =IF(A9<>"","No","") -> No | K10: =IF(A9<>"","No","") -> No | L10: =IFERROR(__xludf.DUMMYFUNCTION("""COMPUTED_VALUE"""),"Wheatland, PA") -> Wheatland, PA | M10: =IFERROR(__xludf.DUMMYFUNCTION("""COMPUTED_VALUE"""),"Reposted 42 minutes ago") -> Reposted 42 minutes ago | N10: =IFERROR(__xludf.DUMMYFUNCTION("""COMPUTED_VALUE"""),42.0) -> 42 | P10: =IF(A9<>"","0","") -> 0 | R10: =IF(A9<>"","Review","") -> Review | Z10: 45962 | AA10: 2025-W44 | AB10: 2025-11 | AC10: =IF(Z10="","", Z10 - WEEKDAY(Z10, 2) + 1) -> 45957 | AD10: =IF(Z10="","", WEEKDAY(Z10, 2)) -> 6
